ERROR: Exception:
Traceback (most recent call last):
  File "C:\Users\saile\Desktop\Selenium-Workspace\YouTube-Comment-Scraper\virtual_env_dependencies\lib\site-packages\pip\_vendor\packaging\markers.py", line 278, in __init__
    self._markers = _coerce_parse_result(MARKER.parseString(marker))
  File "C:\Users\saile\Desktop\Selenium-Workspace\YouTube-Comment-Scraper\virtual_env_dependencies\lib\site-packages\pip\_vendor\pyparsing\core.py", line 1141, in parse_string
    raise exc.with_traceback(None)
pip._vendor.pyparsing.exceptions.ParseException: Expected {Group:({'implementation_version' | 'platform_python_implementation' | 'implementation_name' | 'python_full_version' | 'platform_release' | 'platform_version' | 'platform_machine' | 'platform_system' | 'python_version' | 'sys_platform' | 'os_name' | 'os.name' | 'sys.platform' | 'platform.version' | 'platform.machine' | 'platform.python_implementation' | 'python_implementation' | 'extra'} | {string enclosed in "'" | string enclosed in '"'}} {'===' | '==' | '>=' | '<=' | '!=' | '~=' | '>' | '<' | 'not in' | 'in'} {{'implementation_version' | 'platform_python_implementation' | 'implementation_name' | 'python_full_version' | 'platform_release' | 'platform_version' | 'platform_machine' | 'platform_system' | 'python_version' | 'sys_platform' | 'os_name' | 'os.name' | 'sys.platform' | 'platform.version' | 'platform.machine' | 'platform.python_implementation' | 'python_implementation' | 'extra'} | {string enclosed in "'" | string enclosed in '"'}) | Group:({{Suppress:('(') : ...} Suppress:(')')})}, found '31m'  (at char 0), (line:1, col:1)

During handling of the above exception, another exception occurred:

Traceback (most recent call last):
  File "C:\Users\saile\Desktop\Selenium-Workspace\YouTube-Comment-Scraper\virtual_env_dependencies\lib\site-packages\pip\_internal\cli\base_command.py", line 167, in exc_logging_wrapper
    status = run_func(*args)
  File "C:\Users\saile\Desktop\Selenium-Workspace\YouTube-Comment-Scraper\virtual_env_dependencies\lib\site-packages\pip\_internal\cli\req_command.py", line 247, in wrapper
    return func(self, options, args)
  File "C:\Users\saile\Desktop\Selenium-Workspace\YouTube-Comment-Scraper\virtual_env_dependencies\lib\site-packages\pip\_internal\commands\install.py", line 335, in run
    reqs = self.get_requirements(args, options, finder, session)
  File "C:\Users\saile\Desktop\Selenium-Workspace\YouTube-Comment-Scraper\virtual_env_dependencies\lib\site-packages\pip\_internal\cli\req_command.py", line 411, in get_requirements
    req_to_add = install_req_from_line(
  File "C:\Users\saile\Desktop\Selenium-Workspace\YouTube-Comment-Scraper\virtual_env_dependencies\lib\site-packages\pip\_internal\req\constructors.py", line 393, in install_req_from_line
    parts = parse_req_from_line(name, line_source)
  File "C:\Users\saile\Desktop\Selenium-Workspace\YouTube-Comment-Scraper\virtual_env_dependencies\lib\site-packages\pip\_internal\req\constructors.py", line 297, in parse_req_from_line
    markers = Marker(markers_as_string)
  File "C:\Users\saile\Desktop\Selenium-Workspace\YouTube-Comment-Scraper\virtual_env_dependencies\lib\site-packages\pip\_vendor\packaging\markers.py", line 280, in __init__
    raise InvalidMarker(
pip._vendor.packaging.markers.InvalidMarker: Invalid marker: '31m', parse error at '31m'
WARNING: There was an error checking the latest version of pip.
